Workbook

Sheet Calculator
B1: PERSONAL INJURY CASE VALUATION CALCULATOR
B2: Florida | Hybrid multiplier + per-diem range | Blue cells = inputs. Edit only blue/yellow cells.
B4: CASE INFORMATION
B5: Client name
B6: Claim / file no.
B7: Date of loss
B8: Adjuster / carrier
C9: LOW | D9: HIGH
B10: 1. ECONOMIC DAMAGES (SPECIALS - recoverable)
B11: Past medical bills (billed) | C11: 0
B12: Future medical costs (estimated) | C12: 0
B13: Past lost wages | C13: 0
B14: Future lost earnings / earning capacity | C14: 0
B15: Other out-of-pocket (mileage, meds, devices) | C15: 0
B16: Total economic damages | C16: =SUM(C11:C15) -> 0
B17: Medical specials (past + future) - multiplier base | C17: =C11+C12 -> 0
B19: 2. PAIN & SUFFERING - METHOD A: MULTIPLIER
B20: Injury severity (choose) | C20: 1 - Minor (soft tissue, full recovery)
B21: Suggested multiplier (from severity) | C21: =VLOOKUP($C$20,Reference!$A$2:$C$6,2,FALSE()) -> 1.5 | D21: =VLOOKUP($C$20,Reference!$A$2:$C$6,3,FALSE()) -> 2.5 | E21: low / high
B22: Override multiplier (optional) | E22: Leave blank to use suggested
B23: Multiplier used | C23: =IF(C22="",C21,C22) -> 1.5 | D23: =IF(D22="",D21,D22) -> 2.5
B24: Pain & suffering - Method A (low / high) | C24: =$C$17*C23 -> 0 | D24: =$C$17*D23 -> 0
B26: 3. PAIN & SUFFERING - METHOD B: PER DIEM
B27: Daily rate (low / high) | C27: 150 | D27: 300 | E27: Common: $150-$300/day
B28: Days of pain / impact | C28: 0 | E28: Injury date to MMI, or treatment days
B29: Pain & suffering - Method B (low / high) | C29: =C27*$C$28 -> 0 | D29: =D27*$C$28 -> 0
B31: 4. BLENDED NON-ECONOMIC (BASE)
B32: Non-economic base (low / high) | C32: =IF(AND(C24>0,C29>0),MIN(C24,C29),MAX(C24,C29)) -> 0 | D32: =MAX(D24,D29) -> 0
B33: Method note | E33: If only one method is used, that method sets the range
B35: 5. CASE CHARACTERISTICS (adjust pain & suffering)
B36: Permanent impairment rating (whole-person %) | C36: 0 | D36: =1+MIN(C36,0.4)*1.5 -> 1 | E36: factor
B37: Client age (years) | C37: 40 | D37: =VLOOKUP(C37,Reference!$J$2:$K$7,2,TRUE()) -> 1.05 | E37: factor
B38: Prior accidents / injuries (choose) | C38: None / clean history | D38: =VLOOKUP(C38,Reference!$N$2:$O$5,2,FALSE()) -> 1 | E38: factor
B39: Property damage $ (NOT recoverable - signal only) | C39: 0 | E39: Used for causation check, not added to value
B40: Vehicle / impact severity (choose) | C40: Moderate - drivable with damage | D40: =VLOOKUP(C40,Reference!$Q$2:$R$4,2,FALSE()) -> 1 | E40: factor
B41: Causation check (PD vs. medicals) | C41: =IF(AND($C$39>0,$C$17>0,$C$39<$C$17*0.15),"LOW property damage vs. high medicals - causation EXPOSURE",IF($C$40="Severe - totaled / major impact","High impact - causation & damages well-supported",IF($C$39=0,"Enter PD to run causation check","Property damage consistent with claimed injuries"))) -> Enter PD to run causation check
B42: Composite non-economic modifier | C42: =MAX(0.4,MIN(2,D36*D37*D38*D40)) -> 1.05 | E42: Impairment x age x prior x impact (capped 0.4x-2.0x)
B43: Florida permanency threshold check | C43: =IF(C36>0,"Impairment shown - non-economic threshold likely met","No impairment % - confirm permanency threshold (Fla. Stat. 627.737)") -> No impairment % - confirm permanency threshold (Fla. Stat. 627.737)
B44: Adjusted non-economic (low / high) | C44: =C32*$C$42 -> 0 | D44: =D32*$C$42 -> 0
B46: 6. GROSS CASE VALUE (before risk adjustments)
...

Sheet Reference
A1: Severity | B1: Mult Low | C1: Mult High | D1: Description | F1: Liability | G1: Factor | H1: Meaning | J1: Age from | K1: Factor | L1: Bracket | N1: Prior history | O1: Factor | Q1: Vehicle / impact severity | R1: Factor
A2: 1 - Minor (soft tissue, full recovery) | B2: 1.5 | C2: 2.5 | D2: Sprains/strains, conservative care, no residuals | F2: Clear / strong | G2: 1 | H2: Liability admitted or near-certain | J2: 0 | K2: 1.15 | L2: Under 18 | N2: None / clean history | O2: 1 | Q2: Severe - totaled / major impact | R2: 1.1
A3: 2 - Moderate (treatment, minor residual) | B3: 2.5 | C3: 3.5 | D3: Injections, PT, some lasting discomfort | F3: Probable | G3: 0.85 | H3: Good facts, minor disputes | J3: 18 | K3: 1.15 | L3: 18-29 | N3: Prior - unrelated body part | O3: 0.97 | Q3: Moderate - drivable with damage | R3: 1
A4: 3 - Serious (surgery / objective injury) | B4: 3.5 | C4: 4.5 | D4: Fracture, surgery, MRI-confirmed injury | F4: Disputed | G4: 0.65 | H4: Genuine fact dispute on fault | J4: 30 | K4: 1.05 | L4: 30-49 | N4: Prior - same body part (documented) | O4: 0.8 | Q4: Minor - cosmetic / low impact | R4: 0.85
A5: 4 - Severe (permanent / disfigurement) | B5: 4.5 | C5: 6 | D5: Permanent impairment, scarring, chronic pain | F5: Weak / questionable | G5: 0.4 | H5: Liability is a real problem | J5: 50 | K5: 1 | L5: 50-64 | N5: Prior - same part + recent treatment | O5: 0.7
A6: 5 - Catastrophic (disability, brain/spinal) | B6: 5 | C6: 10 | D6: TBI, paralysis, amputation, lifelong care | J6: 65 | K6: 0.92 | L6: 65-79
J7: 80 | K7: 0.85 | L7: 80+
A8: Impairment factor: 1 + (whole-person impairment % x 1.5), capped at 1.6
A9: Property damage is NOT a recoverable element of the BI claim - used only as a causation/severity signal.

Sheet Guide
B1: HOW TO USE THIS TOOL
B3: Purpose
B4: Quick, consistent first-pass valuation for preparing demands and evaluating opening offers. A starting point for attorney judgment - not a substitute for it.
B5: Step by step
B6: 1. Fill the blue cells under ECONOMIC DAMAGES - past/future medicals, wages, out-of-pocket. These are the recoverable specials.
B7: 2. Pick INJURY SEVERITY (yellow dropdown). The multiplier auto-fills; override only with a reason.
B8: 3. Set the PER DIEM rate and number of pain/impact days (injury date to maximum medical improvement is typical).
B9: 4. Enter CASE CHARACTERISTICS - impairment %, age, prior injuries, and property-damage/impact. These adjust pain & suffering only.
B10: 5. Choose LIABILITY STRENGTH, enter the client's COMPARATIVE FAULT %, and policy limits.
B11: 6. Read the SETTLEMENT TARGET RANGE and OPENING DEMAND. Use section 9 to score any offer.
B12: Methodology
B13: Multiplier method: non-economic = medical specials x severity multiplier (1.5-10x). Per diem: daily rate x recovery days. The blended low is the lower of the two methods; the high is the higher.
... B27: Estimates only; not legal advice. Every case turns on its facts, venue, and the people involved. An attorney must review before any demand is sent or offer accepted.
